<mujoco model="snake">
    <compiler angle="radian" meshdir="assets" autolimits="true"/>
  
    <asset>
      <material name="black" rgba="0.2 0.2 0.2 1"/>
  
      <!-- <mesh name="base" file="base_link.STL"/>
      <mesh name="body" file="body_module.STL"/> -->
      <mesh name="base" file="smaller/base_link.STL"  scale="0.001 0.001 0.001"/>
      <mesh name="body" file="smaller/body_module.STL"  scale="0.001 0.001 0.001"/>
      <mesh name="head" file="smaller/head_module.STL"  scale="0.001 0.001 0.001"/>

    </asset>
  
    <default>
      <geom type="mesh" solref=".004 1"/>
      <joint limited="true" range="-1.570796 1.570796" damping="1.084" armature="0.045" frictionloss="0.03"/>
      <site group="2" type="sphere"/>
      <position kp="21.1" ctrlrange="-3.141592 3.141592" forcerange="-5 5"/>
      <default class="collision">
        <geom group="3"/>
        <default class="foot">
          <geom mass="0" type="box"/>
        </default>
      </default>
      <default class="visual">
        <geom material="black" contype="0" conaffinity="0" group="2"/>
      </default>
    </default>
  
    <worldbody>
      <body name="base" pos="0 0 0" quat="0.7071068 0.7071068 0 0">
        <geom mesh="base" class="visual"/>
        <!-- <geom mesh="body_c" class="collision"/> -->
        <body name="link1" pos="0 0.044 0" quat="0.7071068 0 0.7071068 0">
        <!-- <body name="link1" pos="0 0.01565 0.0427" quat="0.7071068 0 0.7071068 0"> -->
          <!-- <inertial pos="0 0 0" mass="0.0284215307947391" diaginertia="4.61797384662241e-06 3.37759616677652e-06 3.92947315930169e-06"/> -->
          <joint name="joint0" axis="0 0 1" pos="0 -0.0195 0"/>
          <geom mesh="body" class="visual"/>
          <site name="link1_cam0" pos="-0.0184 0.0075 0.0086" size="0.003" rgba="0.0 0.0 1.0 1.0"
                type="cylinder" quat="0.7071068 0 0.7071068 0"/>
          <site name="link1_cam1" pos="0.0184 0.0075 0.0086" size="0.003" rgba="0.0 1.0 0.0 1.0"
                type="cylinder" quat="0.7071068 0 -0.7071068 0"/>
          <!-- <geom mesh="link1_c" class="collision"/> -->
          <!-- <camera name="head_pan_cam" pos="0.02 0 0.01" fovy="43.3" mode="fixed" euler="0.0 -1.570796 -1.570796"/>
          <geom name="head_pan_cam" size="0.02" pos="0.02 0 0.01" type="sphere" rgba="0.8 0.2 0.2 1" class="visual"/> -->
          <body name="link2" pos="0 0.04445 0" quat="0.7071068 0 0.7071068 0">
            <!-- <inertial pos="0 0 0" mass="0.0284215307947391" diaginertia="4.61797384662241e-06 3.37759616677652e-06 3.92947315930169e-06"/> -->
            <joint name="joint1" axis="0 0 1" pos="0 -0.01942 0"/>
            <geom mesh="body" class="visual"/>
            <!-- <site name="link2_cam0" pos="-0.0184 0.0251 0.0086" size="0.01" rgba="0.0 0.0 1.0 1.0"
                  type="cylinder" quat="0.7071068 0 0.7071068 0"/>
            <site name="link2_cam1" pos="0.0184 0.0251 0.0086" size="0.01" rgba="0.0 1.0 0.0 1.0"
                  type="cylinder" quat="0.7071068 0 -0.7071068 0"/> -->
            <!-- <geom mesh="link1_c" class="collision"/> -->
            <body name="link3" pos="0 0.04445 0" quat="0.7071068 0 0.7071068 0">
              <!-- <inertial pos="0 0 0" mass="0.0284215307947391" diaginertia="4.61797384662241e-06 3.37759616677652e-06 3.92947315930169e-06"/> -->
              <joint name="joint2" axis="0 0 1" pos="0 -0.01942 0"/>
              <geom mesh="body" class="visual"/>
              <!-- <site name="link3_cam0" pos="-0.0184 0.0251 -0.0086" size="0.01" rgba="0.0 0.0 1.0 1.0"
                    type="cylinder" quat="0.7071068 0 0.7071068 0"/>
              <site name="link3_cam1" pos="0.0184 0.0251 -0.0086" size="0.01" rgba="0.0 1.0 0.0 1.0"
                    type="cylinder" quat="0.7071068 0 -0.7071068 0"/> -->
              <!-- <geom mesh="link1_c" class="collision"/> -->
              <body name="link4" pos="0 0.04445 0" quat="0.7071068 0 0.7071068 0">
                <!-- <inertial pos="0 0 0" mass="0.0284215307947391" diaginertia="4.61797384662241e-06 3.37759616677652e-06 3.92947315930169e-06"/> -->
                <joint name="joint3" axis="0 0 1" pos="0 -0.01942 0"/>
                <geom mesh="body" class="visual"/>
                <!-- <site name="link4_cam0" pos="-0.0184 0.0251 -0.0086" size="0.01" rgba="0.0 0.0 1.0 1.0"
                      type="cylinder" quat="0.7071068 0 0.7071068 0"/>
                <site name="link4_cam1" pos="0.0184 0.0251 -0.0086" size="0.01" rgba="0.0 1.0 0.0 1.0"
                      type="cylinder" quat="0.7071068 0 -0.7071068 0"/> -->
                <!-- <geom mesh="link1_c" class="collision"/> -->
                <body name="link5" pos="0 0.04445 0" quat="0.7071068 0 0.7071068 0">
                  <!-- <inertial pos="0 0 0" mass="0.0284215307947391" diaginertia="4.61797384662241e-06 3.37759616677652e-06 3.92947315930169e-06"/> -->
                  <joint name="joint4" axis="0 0 1" pos="0 -0.01942 0"/>
                  <geom mesh="body" class="visual"/>
                  <!-- <site name="link5_cam0" pos="-0.0184 0.0251 0.0086" size="0.01" rgba="0.0 0.0 1.0 1.0"
                        type="cylinder" quat="0.7071068 0 0.7071068 0"/>
                  <site name="link5_cam1" pos="0.0184 0.0251 0.0086" size="0.01" rgba="0.0 1.0 0.0 1.0"
                        type="cylinder" quat="0.7071068 0 -0.7071068 0"/> -->
                  <!-- <geom mesh="link1_c" class="collision"/> -->
                  <body name="link6" pos="0 0.04445 0" quat="0.7071068 0 0.7071068 0">
                    <!-- <inertial pos="0 0 0" mass="0.0284215307947391" diaginertia="4.61797384662241e-06 3.37759616677652e-06 3.92947315930169e-06"/> -->
                    <joint name="joint5" axis="0 0 1" pos="0 -0.01942 0"/>
                    <geom mesh="body" class="visual"/>
                    <site name="link6_cam0" pos="-0.0184 0.0075 0.0086" size="0.003" rgba="0.0 0.0 1.0 1.0"
                          type="cylinder" quat="0.7071068 0 0.7071068 0"/>
                    <site name="link6_cam1" pos="0.0184 0.0075 0.0086" size="0.003" rgba="0.0 1.0 0.0 1.0"
                          type="cylinder" quat="0.7071068 0 -0.7071068 0"/>
                    <!-- <geom mesh="link1_c" class="collision"/> -->
                    <body name="link7" pos="0 0.04445 0" quat="0.7071068 0 0.7071068 0">
                      <!-- <inertial pos="0 0 0" mass="0.0284215307947391" diaginertia="4.61797384662241e-06 3.37759616677652e-06 3.92947315930169e-06"/> -->
                      <joint name="joint6" axis="0 0 1" pos="0 -0.01942 0"/>
                      <geom mesh="body" class="visual"/>
                      <site name="link7_cam0" pos="-0.0184 0.0075 0.0086" size="0.003" rgba="0.0 0.0 1.0 1.0"
                            type="cylinder" quat="0.7071068 0 0.7071068 0"/>
                      <site name="link7_cam1" pos="0.0184 0.0075 0.0086" size="0.003" rgba="0.0 1.0 0.0 1.0"
                            type="cylinder" quat="0.7071068 0 -0.7071068 0"/>
                      <!-- <geom mesh="link1_c" class="collision"/> -->
                        <body name="head" pos="0 0.0387 0" quat="0.7071068 0 -0.7071068 0">
                          <!-- <inertial mass="0.0284215307947391" diaginertia="4.61797384662241e-06 3.37759616677652e-06 3.92947315930169e-06"/> -->
                          <joint name="joint7" axis="0 0 1" pos="0 -0.0138 0"/>
                          <geom mesh="head" class="visual"/>
                          <site name="head_center" pos="0 0.0122 -0.002" size="0.003" rgba="0.0 0.0 1.0 1.0"
                                type="cylinder" quat="0.5 0.5 0.5 -0.5"/>
                          <!-- <site name="head_cam_front" pos="-0.0085 0.0195 0.0181" size="0.01" rgba="0.0 0.0 1.0 1.0"
                                type="cylinder" quat="0 0 0.8549 0.5188"/>
                          <site name="head_cam_left" pos="-0.018 0.0195 0.0086" size="0.01" rgba="0.0 1.0 0.0 1.0"
                                type="cylinder" quat="0.39297672 -0.58781951 -0.39297672 -0.58781951"/>
                          <site name="head_cam_back" pos="-0.0085 0.0195 -0.0181" size="0.01" rgba="1.0 0.0 0.0 1.0"
                                type="cylinder" quat="0 0 0.5188 0.8549"/>
                          <site name="head_cam_right" pos="0.018 0.0195 0.0086" size="0.01" rgba="0.0 1.0 1.0 1.0" --> -->
                                <!-- type="cylinder" quat="-0.5878195 0.39297672 0.58781951 0.39297672"/> -->
                          <!-- <geom mesh="link1_c" class="collision"/> -->
                          <!-- <site name="head" pos="0 0.06 0" size="0.02" rgba="0.0 0.0 1.0 1.0"/> -->
                        </body>
                      </body>
                    </body> 
                  </body>
                </body>
              </body>
            </body>
          </body>
 
      </body>
    </worldbody>
  
    <actuator>
      <position name="act0" joint="joint0"/>
      <position name="act1" joint="joint1"/>
      <position name="act2" joint="joint2"/>
      <position name="act3" joint="joint3"/>
      <position name="act4" joint="joint4"/>
      <position name="act5" joint="joint5"/>
      <position name="act6" joint="joint6"/>
      <position name="act7" joint="joint7"/>
    </actuator>
  </mujoco>
  
